Workbook

Sheet ENTRADA_DATOS
A1: TORNILLO SINFÍN
A3: DEFINICIÓN CARACTERISTICAS
A5: MATERIAL: | C5: S355J2+N
A7: DIAMETRO TUBO EJE TORNILLO: | C7: 60.3
A8: Espesor tubo: | C8: 3.2
A9: Nº Partes del Tubo: | C9: 1
A10: Diametro Compra Mangones:
A11: Diametro Eje Final:
A13: FORMA DE LA CAMISA: | C13: CIRCULAR
A15: DIAMETRO EXTERIOR ESPIRA: | C15: 195
A17: PASO ESPIRAS
A18: PASO 1 | C18: 140
A19: PASO 2 | C19: 195
A20: PASO 3
A22: SENTIDO DE GIRO | C22: DERECHAS
A24: LONGITUD ENTRE TESTEROS | C24: 8000
A26: ESPESOR TESTEROS | C26: 5
A28: ESPESOR BRIDAS | C28: 5
A30: TIPO DISPOSICIÓN MOTORREDUCTOR-EJE | C30: COAXIAL
A32: POSICION MOTOREDUCTOR | C32: B7

Sheet HojaPrincipal
A1: LISTADO GENERAL SINFÍN
A3: PARTE 001: TORNILLO
A4: 001.001 | B4: Eje Tubo / Longitud Tubo | C4: =IF(A4<>"",(_xlfn.VALUETOTEXT(A4)&"."& TEXT(ROUND(VALUE($D$4)*10,0),"0000")&"."&_xlfn.VALUETOTEXT($E$4)),"") -> 001.001.0603.3545 | D4: 60.3 | E4: =VALUE(D16)-(2*60) -> 3545 | F4: =VALUE(D4) -> 60.3
A5: 001.002 | B5: Mangon Conducido | C5: =IF(A5<>"",(_xlfn.VALUETOTEXT(A5)&"."& TEXT(ROUND(VALUE($D$4)*10,0),"0000"))&"."&TEXT(ROUND(VALUE(D5)*10,0),"0000"),"") -> 001.002.0603.0550 | D5: =IF($D$37="","",$D$37) -> 55
A6: 001.003 | B6: Mangon de Empalme | C6: =IF(A6<>"",(_xlfn.VALUETOTEXT(A6)&"."& TEXT(ROUND(VALUE($D$4)*10,0),"0000"))&"."&TEXT(ROUND(VALUE(D6)*10,0),"0000"),"") -> 001.003.0603.0550 | D6: =IF($D$37="","",$D$37) -> 55
A7: 001.004 | B7: Mangon Accionamiento | C7: =IF(A7<>"",(_xlfn.VALUETOTEXT(A7)&"."& TEXT(ROUND(VALUE($D$4)*10,0),"0000"))&"."&TEXT(ROUND(VALUE(D7)*10,0),"0000"),"") -> 001.004.0603.0550 | D7: =IF($D$37="","",$D$37) -> 55
A8: 001.005 | B8: Espiras: Cantidad | D8: =ROUNDDOWN((($E$4-100)/$D$11),0) -> 29
B9: Diametro Exterior Espiras | C9: =IF(A9<>"",(_xlfn.VALUETOTEXT(A9)&"."& TEXT(ROUND(VALUE($D$4)*10,0),"0000")&"."&_xlfn.VALUETOTEXT($E$4)),"") | D9: 115 | F9: =VALUE(D9+8) -> 123 | G9: =MIN(LISTA_EJE_TUBO!D2:D500) -> 139.7
B10: Diametro Interior Espiras | C10: =IF(A10<>"",(_xlfn.VALUETOTEXT(A10)&"."& TEXT(ROUND(VALUE($D$4)*10,0),"0000")&"."&_xlfn.VALUETOTEXT($E$4)),"") | D10: =F4+0.5 -> 60.8
B11: Paso 01 espiras | C11: =IF($D$11<>"",(_xlfn.VALUETOTEXT($A$8)&"."& TEXT(ROUND(VALUE($D$4)*10,0),"0000")&"."&TEXT(ROUND(VALUE($D$9),0),"0000")&"."&TEXT(ROUND(VALUE($D$11),0),"0000")),"") -> 001.005.0603.0115.0115 | D11: 115
B12: Paso 02 espiras | C12: =IF($D$12<>"",(_xlfn.VALUETOTEXT($A$8)&"."& TEXT(ROUND(VALUE($D$4)*10,0),"0000")&"."&TEXT(ROUND(VALUE($D$9),0),"0000")&"."&TEXT(ROUND(VALUE($D$12),0),"0000")),"")
A13: 001.006 | B13: Tornilleria | C13: =IF(A13<>"",(_xlfn.VALUETOTEXT(A13)&"."& TEXT(ROUND(VALUE($D$4)*10,0),"0000")&"."&_xlfn.VALUETOTEXT($E$4)),"") -> 001.006.0603.3545 | D13: 4 | E13: M12 | F13: Número de Tornillos para atornillar mangones y tubo
A15: PARTE 002A: CAMISA TUBO ø
A16: Distancia entre Testeros | D16: 3665
A17: 002A.001 | B17: Tubo ø exterior / ø interior | D17: =IFERROR(HojaPrincipal!$G$9,"") -> 139.7 | E17: 131.7
A18: 002A.002 | B18: Testeros | C18: =_xlfn.VALUETOTEXT(A18) & "." & TEXT(ROUND(VALUE($D$17)*10,0),"0000") & "." & TEXT(ROUND(VALUE($E$17)*10,0),"0000")&"."& TEXT(ROUND(VALUE($D$18),0),"0000") -> 002A.002.1397.1317.0005 | D18: 5 | E18: Espesor Chapa
A19: 002A.003 | B19: Ventana Inspeccion | C19: =_xlfn.VALUETOTEXT(A19) & "." & TEXT(ROUND(VALUE($D$17)*10,0),"0000") -> 002A.003.1397
A20: 002A.004 | B20: Cjto. sujeccion mangon intermedio | C20: =_xlfn.VALUETOTEXT(A20) & "." & TEXT(ROUND(VALUE($D$17)*10,0),"0000") & "-" & TEXT(ROUND(VALUE($D$6),0),"0000") -> 002A.004.1397-0055
A21: 002A.005 | B21: Boca Entrada
A22: 002A.006 | B22: Boca Salida
A24: PARTE 002B: CAMISA ARTESA
A25: Distancia entre Testeros
A26: 002B.001 | B26: Chapa Artesa
A27: 002B.002 | B27: Testeros
A28: 002B.003 | B28: Ventana Inspeccion
A29: 002B.004 | B29: Chapa sujeccion mangon intermedio
A30: 002B.005 | B30: Boca Entrada
A31: 002B.006 | B31: Boca Salida
A33: PARTE 003: PARTE CONDUCCION
A34: 003.001 | B34: Brida
A35: 003.002 | B35: Prensaestopas
A36: 003.003 | B36: Bancada Soporte
A37: 003.004 | B37: Cjto Rodamiento | C37: SKF 22211 E | D37: =IF(C37="","",_xlfn.XLOOKUP(C37,'CAT_RODAMIENTOS'!$B:$B,'CAT_RODAMIENTOS'!$C:$C)) -> 55 | E37: =IF(C37="","",_xlfn.XLOOKUP(C37,'CAT_RODAMIENTOS'!$B:$B,'CAT_RODAMIENTOS'!$D:$D)) -> 100 | F37: =IF(C37="","",_xlfn.XLOOKUP(C37,'CAT_RODAMIENTOS'!$B:$B,'CAT_RODAMIENTOS'!$E:$E)) -> 25 | G37: =D37-2*E37 -> -145
A38: 003.005 | B38: Cjto Motor-Reductor
A39: 003.006 | B39: Sellado
A41: PARTE 004: PARTE CONDUCIDO
A42: 004.001 | B42: Brida
A43: 004.002 | B43: Prensaestopas
A44: 004.003 | B44: Bancada Soporte
A45: 004.004 | B45: Cjto Rodamiento
...

Sheet CAT_RODAMIENTOS
A1: Serie | B1: Referencia | C1: d_mm | D1: D_mm.1 | E1: B_mm | F1: Valido_para_EJE
A2: 22208 | B2: SKF 22208 E | C2: 40 | D2: 80 | E2: 23 | F2: =IF(VALUE(C2)<=HojaPrincipal!$F$4,B2,"") -> SKF 22208 E
A3: 22209 | B3: SKF 22209 E | C3: 45 | D3: 85 | E3: 23 | F3: =IF(VALUE(C3)<=HojaPrincipal!$F$4,B3,"") -> SKF 22209 E
A4: 22210 | B4: SKF 22210 E | C4: 50 | D4: 90 | E4: 23 | F4: =IF(VALUE(C4)<=HojaPrincipal!$F$4,B4,"") -> SKF 22210 E
A5: 22211 | B5: SKF 22211 E | C5: 55 | D5: 100 | E5: 25 | F5: =IF(VALUE(C5)<=HojaPrincipal!$F$4,B5,"") -> SKF 22211 E
A6: 22212 | B6: SKF 22212 E | C6: 60 | D6: 110 | E6: 28 | F6: =IF(VALUE(C6)<=HojaPrincipal!$F$4,B6,"") -> SKF 22212 E
A7: 22213 | B7: SKF 22213 E | C7: 65 | D7: 120 | E7: 31 | F7: =IF(VALUE(C7)<=HojaPrincipal!$F$4,B7,"")
A8: 22214 | B8: SKF 22214 E | C8: 70 | D8: 125 | E8: 31 | F8: =IF(VALUE(C8)<=HojaPrincipal!$F$4,B8,"")
A9: 22215 | B9: SKF 22215 E | C9: 75 | D9: 130 | E9: 31 | F9: =IF(VALUE(C9)<=HojaPrincipal!$F$4,B9,"")
A10: 22216 | B10: SKF 22216 E | C10: 80 | D10: 140 | E10: 33 | F10: =IF(VALUE(C10)<=HojaPrincipal!$F$4,B10,"")
A11: 22217 | B11: SKF 22217 E | C11: 85 | D11: 150 | E11: 36 | F11: =IF(VALUE(C11)<=HojaPrincipal!$F$4,B11,"")
A12: 22218 | B12: SKF 22218 E | C12: 90 | D12: 160 | E12: 40 | F12: =IF(VALUE(C12)<=HojaPrincipal!$F$4,B12,"")
A13: 22220 | B13: SKF 22220 E | C13: 100 | D13: 180 | E13: 46 | F13: =IF(VALUE(C13)<=HojaPrincipal!$F$4,B13,"")
... A23: 22320 | B23: SKF 22320 E | C23: 100 | D23: 215 | E23: 73 | F23: =IF(VALUE(C23)<=HojaPrincipal!$F$4,B23,"")

Sheet LISTA_EJE_TUBO
A1: D_exterior_mm | B1: Espesor_mm | C1: d_interior_mm | D1: Valores filtrados | E1: Plano Testeros | F1: d_int_VALIDO | G1: Filtrado espesores
A2: 21.3 | B2: 2 | C2: =Lissta_tubos__2[[#This Row],[D_exterior_mm]]-(2*Lissta_tubos__2[[#This Row],[Espesor_mm]]) -> 17.3 | D2: =IF(C2>=HojaPrincipal!$F$9,A2,"") | E2: =HojaPrincipal!$A$18 & "." & TEXT(ROUND(A2*10,0),"0000") & "-" & TEXT(ROUND(C2*10,0),"0000") -> 002A.002.0213-0173 | F2: =IF(A2=HojaPrincipal!$D$17,C2,"") | G2: =IF(A2=HojaPrincipal!$F$4,B2,"")
A3: 21.3 | B3: 2.3 | C3: =Lissta_tubos__2[[#This Row],[D_exterior_mm]]-(2*Lissta_tubos__2[[#This Row],[Espesor_mm]]) -> 16.7 | D3: =IF(C3>=HojaPrincipal!$F$9,A3,"") | E3: =HojaPrincipal!$A$18 & "." & TEXT(ROUND(A3*10,0),"0000") & "-" & TEXT(ROUND(C3*10,0),"0000") -> 002A.002.0213-0167 | F3: =IF(A3=HojaPrincipal!$D$17,C3,"") | G3: =IF(A3=HojaPrincipal!$F$4,B3,"")
A4: 21.3 | B4: 2.6 | C4: =Lissta_tubos__2[[#This Row],[D_exterior_mm]]-(2*Lissta_tubos__2[[#This Row],[Espesor_mm]]) -> 16.1 | D4: =IF(C4>=HojaPrincipal!$F$9,A4,"") | E4: =HojaPrincipal!$A$18 & "." & TEXT(ROUND(A4*10,0),"0000") & "-" & TEXT(ROUND(C4*10,0),"0000") -> 002A.002.0213-0161 | F4: =IF(A4=HojaPrincipal!$D$17,C4,"") | G4: =IF(A4=HojaPrincipal!$F$4,B4,"")
A5: 21.3 | B5: 3 | C5: =Lissta_tubos__2[[#This Row],[D_exterior_mm]]-(2*Lissta_tubos__2[[#This Row],[Espesor_mm]]) -> 15.3 | D5: =IF(C5>=HojaPrincipal!$F$9,A5,"") | E5: =HojaPrincipal!$A$18 & "." & TEXT(ROUND(A5*10,0),"0000") & "-" & TEXT(ROUND(C5*10,0),"0000") -> 002A.002.0213-0153 | F5: =IF(A5=HojaPrincipal!$D$17,C5,"") | G5: =IF(A5=HojaPrincipal!$F$4,B5,"")
A6: 26.9 | B6: 2 | C6: =Lissta_tubos__2[[#This Row],[D_exterior_mm]]-(2*Lissta_tubos__2[[#This Row],[Espesor_mm]]) -> 22.9 | D6: =IF(C6>=HojaPrincipal!$F$9,A6,"") | E6: =HojaPrincipal!$A$18 & "." & TEXT(ROUND(A6*10,0),"0000") & "-" & TEXT(ROUND(C6*10,0),"0000") -> 002A.002.0269-0229 | F6: =IF(A6=HojaPrincipal!$D$17,C6,"") | G6: =IF(A6=HojaPrincipal!$F$4,B6,"")
A7: 26.9 | B7: 2.3 | C7: =Lissta_tubos__2[[#This Row],[D_exterior_mm]]-(2*Lissta_tubos__2[[#This Row],[Espesor_mm]]) -> 22.3 | D7: =IF(C7>=HojaPrincipal!$F$9,A7,"") | E7: =HojaPrincipal!$A$18 & "." & TEXT(ROUND(A7*10,0),"0000") & "-" & TEXT(ROUND(C7*10,0),"0000") -> 002A.002.0269-0223 | F7: =IF(A7=HojaPrincipal!$D$17,C7,"") | G7: =IF(A7=HojaPrincipal!$F$4,B7,"")
A8: 26.9 | B8: 2.6 | C8: =Lissta_tubos__2[[#This Row],[D_exterior_mm]]-(2*Lissta_tubos__2[[#This Row],[Espesor_mm]]) -> 21.7 | D8: =IF(C8>=HojaPrincipal!$F$9,A8,"") | E8: =HojaPrincipal!$A$18 & "." & TEXT(ROUND(A8*10,0),"0000") & "-" & TEXT(ROUND(C8*10,0),"0000") -> 002A.002.0269-0217 | F8: =IF(A8=HojaPrincipal!$D$17,C8,"") | G8: =IF(A8=HojaPrincipal!$F$4,B8,"")
A9: 26.9 | B9: 3 | C9: =Lissta_tubos__2[[#This Row],[D_exterior_mm]]-(2*Lissta_tubos__2[[#This Row],[Espesor_mm]]) -> 20.9 | D9: =IF(C9>=HojaPrincipal!$F$9,A9,"") | E9: =HojaPrincipal!$A$18 & "." & TEXT(ROUND(A9*10,0),"0000") & "-" & TEXT(ROUND(C9*10,0),"0000") -> 002A.002.0269-0209 | F9: =IF(A9=HojaPrincipal!$D$17,C9,"") | G9: =IF(A9=HojaPrincipal!$F$4,B9,"")
A10: 26.9 | B10: 3.2 | C10: =Lissta_tubos__2[[#This Row],[D_exterior_mm]]-(2*Lissta_tubos__2[[#This Row],[Espesor_mm]]) -> 20.5 | D10: =IF(C10>=HojaPrincipal!$F$9,A10,"") | E10: =HojaPrincipal!$A$18 & "." & TEXT(ROUND(A10*10,0),"0000") & "-" & TEXT(ROUND(C10*10,0),"0000") -> 002A.002.0269-0205 | F10: =IF(A10=HojaPrincipal!$D$17,C10,"") | G10: =IF(A10=HojaPrincipal!$F$4,B10,"")
A11: 33.7 | B11: 2 | C11: =Lissta_tubos__2[[#This Row],[D_exterior_mm]]-(2*Lissta_tubos__2[[#This Row],[Espesor_mm]]) -> 29.7 | D11: =IF(C11>=HojaPrincipal!$F$9,A11,"") | E11: =HojaPrincipal!$A$18 & "." & TEXT(ROUND(A11*10,0),"0000") & "-" & TEXT(ROUND(C11*10,0),"0000") -> 002A.002.0337-0297 | F11: =IF(A11=HojaPrincipal!$D$17,C11,"") | G11: =IF(A11=HojaPrincipal!$F$4,B11,"")
A12: 33.7 | B12: 2.3 | C12: =Lissta_tubos__2[[#This Row],[D_exterior_mm]]-(2*Lissta_tubos__2[[#This Row],[Espesor_mm]]) -> 29.1 | D12: =IF(C12>=HojaPrincipal!$F$9,A12,"") | E12: =HojaPrincipal!$A$18 & "." & TEXT(ROUND(A12*10,0),"0000") & "-" & TEXT(ROUND(C12*10,0),"0000") -> 002A.002.0337-0291 | F12: =IF(A12=HojaPrincipal!$D$17,C12,"") | G12: =IF(A12=HojaPrincipal!$F$4,B12,"")
A13: 33.7 | B13: 2.6 | C13: =Lissta_tubos__2[[#This Row],[D_exterior_mm]]-(2*Lissta_tubos__2[[#This Row],[Espesor_mm]]) -> 28.5 | D13: =IF(C13>=HojaPrincipal!$F$9,A13,"") | E13: =HojaPrincipal!$A$18 & "." & TEXT(ROUND(A13*10,0),"0000") & "-" & TEXT(ROUND(C13*10,0),"0000") -> 002A.002.0337-0285 | F13: =IF(A13=HojaPrincipal!$D$17,C13,"") | G13: =IF(A13=HojaPrincipal!$F$4,B13,"")
... A82: 508 | B82: 10 | C82: =Lissta_tubos__2[[#This Row],[D_exterior_mm]]-(2*Lissta_tubos__2[[#This Row],[Espesor_mm]]) -> 488 | D82: =IF(C82>=HojaPrincipal!$F$9,A82,"") -> 508 | E82: =HojaPrincipal!$A$18 & "." & TEXT(ROUND(A82*10,0),"0000") & "-" & TEXT(ROUND(C82*10,0),"0000") -> 002A.002.5080-4880 | F82: =IF(A82=HojaPrincipal!$D$17,C82,"") | G82: =IF(A82=HojaPrincipal!$F$4,B82,"")

Sheet LISTA_MATERIALES
A2: S275JR
A3: S355J2+N
A4: HARDOX 400
A5: HARDOX 450
A6: HARDOX 500
A7: AISI 304
A8: AISI 316

Sheet DIAMETROS Y PASOS
A1: Diametro Exterior Espira | B1: Pasos Espiras | C1: Espesor Chapa | D1: Longitud Entre Testeros | E1: TIPO MOTORREDUCTOR | F1: POSICION MOTOREDUCTOR | G1: GIRO
A2: 10 | B2: 10 | C2: 1 | D2: 1500 | E2: COAXIAL | F2: B3 | G2: DERECHAS
A3: 15 | B3: 15 | C3: 1.5 | D3: 1550 | E3: ORTOGONAL | F3: B6 | G3: IZQUIERDAS
A4: 20 | B4: 20 | C4: 2 | D4: 1600 | E4: PENDULAR | F4: B7
A5: 25 | B5: 25 | C5: 2.5 | D5: 1650 | F5: B8
A6: 30 | B6: 30 | C6: 3 | D6: 1700 | F6: V5
A7: 35 | B7: 35 | C7: 4 | D7: 1750 | F7: V6
A8: 40 | B8: 40 | C8: 5 | D8: 1800
A9: 45 | B9: 45 | C9: 6 | D9: 1850
A10: 50 | B10: 50 | C10: 8 | D10: 1900
A11: 55 | B11: 55 | C11: 10 | D11: 1950
A12: 60 | B12: 60 | C12: 12 | D12: 2000
A13: 65 | B13: 65 | C13: 14 | D13: 2050
A14: 70 | B14: 70 | C14: 15 | D14: 2100
A15: 75 | B15: 75 | C15: 16 | D15: 2150
A16: 80 | B16: 80 | C16: 18 | D16: 2200
A17: 85 | B17: 85 | C17: 20 | D17: 2250
A18: 90 | B18: 90 | C18: 25 | D18: 2300
A19: 95 | B19: 95 | C19: 30 | D19: 2350
... A21: 105 | B21: 105 | C21: 40 | D21: 2450
A22: 110 | B22: 110 | D22: 2500
A23: 115 | B23: 115 | D23: 2550
A24: 120 | B24: 120 | D24: 2600
A25: 125 | B25: 125 | D25: 2650
A26: 130 | B26: 130 | D26: 2700
A27: 135 | B27: 135 | D27: 2750
A28: 140 | B28: 140 | D28: 2800
A29: 145 | B29: 145 | D29: 2850
A30: 150 | B30: 150 | D30: 2900
A31: 155 | B31: 155 | D31: 2950
A32: 160 | B32: 160 | D32: 3000
A33: 165 | B33: 165 | D33: 3050
... A100: 500 | B100: 500 | D100: 6400
D101: 6450
D102: 6500
D103: 6550
D104: 6600
D105: 6650
D106: 6700
D107: 6750
...
